{
 "cells": [
  {
   "cell_type": "code",
   "execution_count": 1,
   "metadata": {
    "collapsed": true
   },
   "outputs": [],
   "source": [
    "import theano"
   ]
  },
  {
   "cell_type": "code",
   "execution_count": 3,
   "metadata": {
    "collapsed": false
   },
   "outputs": [
    {
     "name": "stdout",
     "output_type": "stream",
     "text": [
      "[Elemwise{exp,no_inplace}(<TensorType(float64, vector)>)]\n",
      "Looping 1000 times took 1.463980 seconds\n",
      "Result is [ 1.23178032  1.61879341  1.52278065 ...,  2.20771815  2.29967753\n",
      "  1.62323285]\n",
      "Used the cpu\n"
     ]
    }
   ],
   "source": [
    "from theano import function, config, shared, tensor, sandbox\n",
    "import numpy\n",
    "import time\n",
    "\n",
    "vlen = 10 * 30 * 768  # 10 x #cores x # threads per core\n",
    "iters = 1000\n",
    "rng = numpy.random.RandomState(22)\n",
    "x = shared(numpy.asarray(rng.rand(vlen), config.floatX))\n",
    "f = function([], tensor.exp(x))\n",
    "print(f.maker.fgraph.toposort())\n",
    "t0 = time.time()\n",
    "\n",
    "\n",
    "for i in range(iters):\n",
    "    r = f()\n",
    "t1 = time.time()\n",
    "print(\"Looping %d times took %f seconds\" % (iters, t1 - t0))\n",
    "print(\"Result is %s\" % (r,))\n",
    "if numpy.any([isinstance(x.op, tensor.Elemwise) and\n",
    "    ('Gpu' not in type(x.op).__name__)\n",
    "    for x in f.maker.fgraph.toposort()]):\n",
    "    print('Used the cpu')\n",
    "else:\n",
    "    print('Used the gpu')"
   ]
  },
  {
   "cell_type": "code",
   "execution_count": 1,
   "metadata": {
    "collapsed": false
   },
   "outputs": [],
   "source": [
    "import pygpu"
   ]
  },
  {
   "cell_type": "code",
   "execution_count": 2,
   "metadata": {
    "collapsed": false
   },
   "outputs": [
    {
     "name": "stdout",
     "output_type": "stream",
     "text": [
      "pygpu is installed in /Users/akihiroaida/.pyenv/versions/anaconda3-4.3.0/lib/python3.6/site-packages/pygpu\n",
      "NumPy version 1.11.3\n",
      "NumPy relaxed strides checking option: False\n",
      "NumPy is installed in /Users/akihiroaida/.pyenv/versions/anaconda3-4.3.0/lib/python3.6/site-packages/numpy\n",
      "Python version 3.6.1 |Anaconda custom (x86_64)| (default, May 11 2017, 13:04:09) [GCC 4.2.1 Compatible Apple LLVM 6.0 (clang-600.0.57)]\n",
      "nose version 1.3.7\n"
     ]
    },
    {
     "name": "stderr",
     "output_type": "stream",
     "text": [
      "EEEEEEE\n",
      "======================================================================\n",
      "ERROR: Failure: RuntimeError (No test device specified.  Specify one using the DEVICE or GPUARRAY_TEST_DEVICE environment variables.)\n",
      "----------------------------------------------------------------------\n",
      "Traceback (most recent call last):\n",
      "  File \"/Users/akihiroaida/.pyenv/versions/anaconda3-4.3.0/lib/python3.6/site-packages/nose/failure.py\", line 39, in runTest\n",
      "    raise self.exc_val.with_traceback(self.tb)\n",
      "  File \"/Users/akihiroaida/.pyenv/versions/anaconda3-4.3.0/lib/python3.6/site-packages/nose/loader.py\", line 417, in loadTestsFromName\n",
      "    addr.filename, addr.module)\n",
      "  File \"/Users/akihiroaida/.pyenv/versions/anaconda3-4.3.0/lib/python3.6/site-packages/nose/importer.py\", line 47, in importFromPath\n",
      "    return self.importFromDir(dir_path, fqname)\n",
      "  File \"/Users/akihiroaida/.pyenv/versions/anaconda3-4.3.0/lib/python3.6/site-packages/nose/importer.py\", line 94, in importFromDir\n",
      "    mod = load_module(part_fqname, fh, filename, desc)\n",
      "  File \"/Users/akihiroaida/.pyenv/versions/anaconda3-4.3.0/lib/python3.6/imp.py\", line 234, in load_module\n",
      "    return load_source(name, filename, file)\n",
      "  File \"/Users/akihiroaida/.pyenv/versions/anaconda3-4.3.0/lib/python3.6/imp.py\", line 172, in load_source\n",
      "    module = _load(spec)\n",
      "  File \"<frozen importlib._bootstrap>\", line 675, in _load\n",
      "  File \"<frozen importlib._bootstrap>\", line 655, in _load_unlocked\n",
      "  File \"<frozen importlib._bootstrap_external>\", line 678, in exec_module\n",
      "  File \"<frozen importlib._bootstrap>\", line 205, in _call_with_frames_removed\n",
      "  File \"/Users/akihiroaida/.pyenv/versions/anaconda3-4.3.0/lib/python3.6/site-packages/pygpu/tests/test_basic.py\", line 5, in <module>\n",
      "    from .support import (gen_gpuarray, context)\n",
      "  File \"/Users/akihiroaida/.pyenv/versions/anaconda3-4.3.0/lib/python3.6/site-packages/pygpu/tests/support.py\", line 32, in <module>\n",
      "    context = gpuarray.init(get_env_dev())\n",
      "  File \"/Users/akihiroaida/.pyenv/versions/anaconda3-4.3.0/lib/python3.6/site-packages/pygpu/tests/support.py\", line 29, in get_env_dev\n",
      "    raise RuntimeError(\"No test device specified.  Specify one using the DEVICE or GPUARRAY_TEST_DEVICE environment variables.\")\n",
      "RuntimeError: No test device specified.  Specify one using the DEVICE or GPUARRAY_TEST_DEVICE environment variables.\n",
      "\n",
      "======================================================================\n",
      "ERROR: Failure: RuntimeError (No test device specified.  Specify one using the DEVICE or GPUARRAY_TEST_DEVICE environment variables.)\n",
      "----------------------------------------------------------------------\n",
      "Traceback (most recent call last):\n",
      "  File \"/Users/akihiroaida/.pyenv/versions/anaconda3-4.3.0/lib/python3.6/site-packages/nose/failure.py\", line 39, in runTest\n",
      "    raise self.exc_val.with_traceback(self.tb)\n",
      "  File \"/Users/akihiroaida/.pyenv/versions/anaconda3-4.3.0/lib/python3.6/site-packages/nose/loader.py\", line 417, in loadTestsFromName\n",
      "    addr.filename, addr.module)\n",
      "  File \"/Users/akihiroaida/.pyenv/versions/anaconda3-4.3.0/lib/python3.6/site-packages/nose/importer.py\", line 47, in importFromPath\n",
      "    return self.importFromDir(dir_path, fqname)\n",
      "  File \"/Users/akihiroaida/.pyenv/versions/anaconda3-4.3.0/lib/python3.6/site-packages/nose/importer.py\", line 94, in importFromDir\n",
      "    mod = load_module(part_fqname, fh, filename, desc)\n",
      "  File \"/Users/akihiroaida/.pyenv/versions/anaconda3-4.3.0/lib/python3.6/imp.py\", line 234, in load_module\n",
      "    return load_source(name, filename, file)\n",
      "  File \"/Users/akihiroaida/.pyenv/versions/anaconda3-4.3.0/lib/python3.6/imp.py\", line 172, in load_source\n",
      "    module = _load(spec)\n",
      "  File \"<frozen importlib._bootstrap>\", line 675, in _load\n",
      "  File \"<frozen importlib._bootstrap>\", line 655, in _load_unlocked\n",
      "  File \"<frozen importlib._bootstrap_external>\", line 678, in exec_module\n",
      "  File \"<frozen importlib._bootstrap>\", line 205, in _call_with_frames_removed\n",
      "  File \"/Users/akihiroaida/.pyenv/versions/anaconda3-4.3.0/lib/python3.6/site-packages/pygpu/tests/test_blas.py\", line 5, in <module>\n",
      "    from .support import (guard_devsup, gen_gpuarray, context)\n",
      "  File \"/Users/akihiroaida/.pyenv/versions/anaconda3-4.3.0/lib/python3.6/site-packages/pygpu/tests/support.py\", line 32, in <module>\n",
      "    context = gpuarray.init(get_env_dev())\n",
      "  File \"/Users/akihiroaida/.pyenv/versions/anaconda3-4.3.0/lib/python3.6/site-packages/pygpu/tests/support.py\", line 29, in get_env_dev\n",
      "    raise RuntimeError(\"No test device specified.  Specify one using the DEVICE or GPUARRAY_TEST_DEVICE environment variables.\")\n",
      "RuntimeError: No test device specified.  Specify one using the DEVICE or GPUARRAY_TEST_DEVICE environment variables.\n",
      "\n",
      "======================================================================\n",
      "ERROR: Failure: RuntimeError (No test device specified.  Specify one using the DEVICE or GPUARRAY_TEST_DEVICE environment variables.)\n",
      "----------------------------------------------------------------------\n",
      "Traceback (most recent call last):\n",
      "  File \"/Users/akihiroaida/.pyenv/versions/anaconda3-4.3.0/lib/python3.6/site-packages/nose/failure.py\", line 39, in runTest\n",
      "    raise self.exc_val.with_traceback(self.tb)\n",
      "  File \"/Users/akihiroaida/.pyenv/versions/anaconda3-4.3.0/lib/python3.6/site-packages/nose/loader.py\", line 417, in loadTestsFromName\n",
      "    addr.filename, addr.module)\n",
      "  File \"/Users/akihiroaida/.pyenv/versions/anaconda3-4.3.0/lib/python3.6/site-packages/nose/importer.py\", line 47, in importFromPath\n",
      "    return self.importFromDir(dir_path, fqname)\n",
      "  File \"/Users/akihiroaida/.pyenv/versions/anaconda3-4.3.0/lib/python3.6/site-packages/nose/importer.py\", line 94, in importFromDir\n",
      "    mod = load_module(part_fqname, fh, filename, desc)\n",
      "  File \"/Users/akihiroaida/.pyenv/versions/anaconda3-4.3.0/lib/python3.6/imp.py\", line 234, in load_module\n",
      "    return load_source(name, filename, file)\n",
      "  File \"/Users/akihiroaida/.pyenv/versions/anaconda3-4.3.0/lib/python3.6/imp.py\", line 172, in load_source\n",
      "    module = _load(spec)\n",
      "  File \"<frozen importlib._bootstrap>\", line 675, in _load\n",
      "  File \"<frozen importlib._bootstrap>\", line 655, in _load_unlocked\n",
      "  File \"<frozen importlib._bootstrap_external>\", line 678, in exec_module\n",
      "  File \"<frozen importlib._bootstrap>\", line 205, in _call_with_frames_removed\n",
      "  File \"/Users/akihiroaida/.pyenv/versions/anaconda3-4.3.0/lib/python3.6/site-packages/pygpu/tests/test_elemwise.py\", line 13, in <module>\n",
      "    from .support import (guard_devsup, context, gen_gpuarray, check_meta_content)\n",
      "  File \"/Users/akihiroaida/.pyenv/versions/anaconda3-4.3.0/lib/python3.6/site-packages/pygpu/tests/support.py\", line 32, in <module>\n",
      "    context = gpuarray.init(get_env_dev())\n",
      "  File \"/Users/akihiroaida/.pyenv/versions/anaconda3-4.3.0/lib/python3.6/site-packages/pygpu/tests/support.py\", line 29, in get_env_dev\n",
      "    raise RuntimeError(\"No test device specified.  Specify one using the DEVICE or GPUARRAY_TEST_DEVICE environment variables.\")\n",
      "RuntimeError: No test device specified.  Specify one using the DEVICE or GPUARRAY_TEST_DEVICE environment variables.\n",
      "\n",
      "======================================================================\n",
      "ERROR: Failure: RuntimeError (No test device specified.  Specify one using the DEVICE or GPUARRAY_TEST_DEVICE environment variables.)\n",
      "----------------------------------------------------------------------\n",
      "Traceback (most recent call last):\n",
      "  File \"/Users/akihiroaida/.pyenv/versions/anaconda3-4.3.0/lib/python3.6/site-packages/nose/failure.py\", line 39, in runTest\n",
      "    raise self.exc_val.with_traceback(self.tb)\n",
      "  File \"/Users/akihiroaida/.pyenv/versions/anaconda3-4.3.0/lib/python3.6/site-packages/nose/loader.py\", line 417, in loadTestsFromName\n",
      "    addr.filename, addr.module)\n",
      "  File \"/Users/akihiroaida/.pyenv/versions/anaconda3-4.3.0/lib/python3.6/site-packages/nose/importer.py\", line 47, in importFromPath\n",
      "    return self.importFromDir(dir_path, fqname)\n",
      "  File \"/Users/akihiroaida/.pyenv/versions/anaconda3-4.3.0/lib/python3.6/site-packages/nose/importer.py\", line 94, in importFromDir\n",
      "    mod = load_module(part_fqname, fh, filename, desc)\n",
      "  File \"/Users/akihiroaida/.pyenv/versions/anaconda3-4.3.0/lib/python3.6/imp.py\", line 234, in load_module\n",
      "    return load_source(name, filename, file)\n",
      "  File \"/Users/akihiroaida/.pyenv/versions/anaconda3-4.3.0/lib/python3.6/imp.py\", line 172, in load_source\n",
      "    module = _load(spec)\n",
      "  File \"<frozen importlib._bootstrap>\", line 675, in _load\n",
      "  File \"<frozen importlib._bootstrap>\", line 655, in _load_unlocked\n",
      "  File \"<frozen importlib._bootstrap_external>\", line 678, in exec_module\n",
      "  File \"<frozen importlib._bootstrap>\", line 205, in _call_with_frames_removed\n",
      "  File \"/Users/akihiroaida/.pyenv/versions/anaconda3-4.3.0/lib/python3.6/site-packages/pygpu/tests/test_gpu_ndarray.py\", line 15, in <module>\n",
      "    from .support import (guard_devsup, check_meta, check_flags, check_all,\n",
      "  File \"/Users/akihiroaida/.pyenv/versions/anaconda3-4.3.0/lib/python3.6/site-packages/pygpu/tests/support.py\", line 32, in <module>\n",
      "    context = gpuarray.init(get_env_dev())\n",
      "  File \"/Users/akihiroaida/.pyenv/versions/anaconda3-4.3.0/lib/python3.6/site-packages/pygpu/tests/support.py\", line 29, in get_env_dev\n",
      "    raise RuntimeError(\"No test device specified.  Specify one using the DEVICE or GPUARRAY_TEST_DEVICE environment variables.\")\n",
      "RuntimeError: No test device specified.  Specify one using the DEVICE or GPUARRAY_TEST_DEVICE environment variables.\n",
      "\n",
      "======================================================================\n",
      "ERROR: Failure: RuntimeError (No test device specified.  Specify one using the DEVICE or GPUARRAY_TEST_DEVICE environment variables.)\n",
      "----------------------------------------------------------------------\n",
      "Traceback (most recent call last):\n",
      "  File \"/Users/akihiroaida/.pyenv/versions/anaconda3-4.3.0/lib/python3.6/site-packages/nose/failure.py\", line 39, in runTest\n",
      "    raise self.exc_val.with_traceback(self.tb)\n",
      "  File \"/Users/akihiroaida/.pyenv/versions/anaconda3-4.3.0/lib/python3.6/site-packages/nose/loader.py\", line 417, in loadTestsFromName\n",
      "    addr.filename, addr.module)\n",
      "  File \"/Users/akihiroaida/.pyenv/versions/anaconda3-4.3.0/lib/python3.6/site-packages/nose/importer.py\", line 47, in importFromPath\n",
      "    return self.importFromDir(dir_path, fqname)\n",
      "  File \"/Users/akihiroaida/.pyenv/versions/anaconda3-4.3.0/lib/python3.6/site-packages/nose/importer.py\", line 94, in importFromDir\n",
      "    mod = load_module(part_fqname, fh, filename, desc)\n",
      "  File \"/Users/akihiroaida/.pyenv/versions/anaconda3-4.3.0/lib/python3.6/imp.py\", line 234, in load_module\n",
      "    return load_source(name, filename, file)\n",
      "  File \"/Users/akihiroaida/.pyenv/versions/anaconda3-4.3.0/lib/python3.6/imp.py\", line 172, in load_source\n",
      "    module = _load(spec)\n",
      "  File \"<frozen importlib._bootstrap>\", line 675, in _load\n",
      "  File \"<frozen importlib._bootstrap>\", line 655, in _load_unlocked\n",
      "  File \"<frozen importlib._bootstrap_external>\", line 678, in exec_module\n",
      "  File \"<frozen importlib._bootstrap>\", line 205, in _call_with_frames_removed\n",
      "  File \"/Users/akihiroaida/.pyenv/versions/anaconda3-4.3.0/lib/python3.6/site-packages/pygpu/tests/test_operations.py\", line 4, in <module>\n",
      "    from .support import (gen_gpuarray, context, SkipTest)\n",
      "  File \"/Users/akihiroaida/.pyenv/versions/anaconda3-4.3.0/lib/python3.6/site-packages/pygpu/tests/support.py\", line 32, in <module>\n",
      "    context = gpuarray.init(get_env_dev())\n",
      "  File \"/Users/akihiroaida/.pyenv/versions/anaconda3-4.3.0/lib/python3.6/site-packages/pygpu/tests/support.py\", line 29, in get_env_dev\n",
      "    raise RuntimeError(\"No test device specified.  Specify one using the DEVICE or GPUARRAY_TEST_DEVICE environment variables.\")\n",
      "RuntimeError: No test device specified.  Specify one using the DEVICE or GPUARRAY_TEST_DEVICE environment variables.\n",
      "\n",
      "======================================================================\n",
      "ERROR: Failure: RuntimeError (No test device specified.  Specify one using the DEVICE or GPUARRAY_TEST_DEVICE environment variables.)\n",
      "----------------------------------------------------------------------\n",
      "Traceback (most recent call last):\n",
      "  File \"/Users/akihiroaida/.pyenv/versions/anaconda3-4.3.0/lib/python3.6/site-packages/nose/failure.py\", line 39, in runTest\n",
      "    raise self.exc_val.with_traceback(self.tb)\n",
      "  File \"/Users/akihiroaida/.pyenv/versions/anaconda3-4.3.0/lib/python3.6/site-packages/nose/loader.py\", line 417, in loadTestsFromName\n",
      "    addr.filename, addr.module)\n",
      "  File \"/Users/akihiroaida/.pyenv/versions/anaconda3-4.3.0/lib/python3.6/site-packages/nose/importer.py\", line 47, in importFromPath\n",
      "    return self.importFromDir(dir_path, fqname)\n",
      "  File \"/Users/akihiroaida/.pyenv/versions/anaconda3-4.3.0/lib/python3.6/site-packages/nose/importer.py\", line 94, in importFromDir\n",
      "    mod = load_module(part_fqname, fh, filename, desc)\n",
      "  File \"/Users/akihiroaida/.pyenv/versions/anaconda3-4.3.0/lib/python3.6/imp.py\", line 234, in load_module\n",
      "    return load_source(name, filename, file)\n",
      "  File \"/Users/akihiroaida/.pyenv/versions/anaconda3-4.3.0/lib/python3.6/imp.py\", line 172, in load_source\n",
      "    module = _load(spec)\n",
      "  File \"<frozen importlib._bootstrap>\", line 675, in _load\n",
      "  File \"<frozen importlib._bootstrap>\", line 655, in _load_unlocked\n",
      "  File \"<frozen importlib._bootstrap_external>\", line 678, in exec_module\n",
      "  File \"<frozen importlib._bootstrap>\", line 205, in _call_with_frames_removed\n",
      "  File \"/Users/akihiroaida/.pyenv/versions/anaconda3-4.3.0/lib/python3.6/site-packages/pygpu/tests/test_reduction.py\", line 8, in <module>\n",
      "    from .support import (guard_devsup, check_meta_content, context, gen_gpuarray,\n",
      "  File \"/Users/akihiroaida/.pyenv/versions/anaconda3-4.3.0/lib/python3.6/site-packages/pygpu/tests/support.py\", line 32, in <module>\n",
      "    context = gpuarray.init(get_env_dev())\n",
      "  File \"/Users/akihiroaida/.pyenv/versions/anaconda3-4.3.0/lib/python3.6/site-packages/pygpu/tests/support.py\", line 29, in get_env_dev\n",
      "    raise RuntimeError(\"No test device specified.  Specify one using the DEVICE or GPUARRAY_TEST_DEVICE environment variables.\")\n",
      "RuntimeError: No test device specified.  Specify one using the DEVICE or GPUARRAY_TEST_DEVICE environment variables.\n",
      "\n",
      "======================================================================\n",
      "ERROR: Failure: RuntimeError (No test device specified.  Specify one using the DEVICE or GPUARRAY_TEST_DEVICE environment variables.)\n",
      "----------------------------------------------------------------------\n",
      "Traceback (most recent call last):\n",
      "  File \"/Users/akihiroaida/.pyenv/versions/anaconda3-4.3.0/lib/python3.6/site-packages/nose/failure.py\", line 39, in runTest\n",
      "    raise self.exc_val.with_traceback(self.tb)\n",
      "  File \"/Users/akihiroaida/.pyenv/versions/anaconda3-4.3.0/lib/python3.6/site-packages/nose/loader.py\", line 417, in loadTestsFromName\n",
      "    addr.filename, addr.module)\n",
      "  File \"/Users/akihiroaida/.pyenv/versions/anaconda3-4.3.0/lib/python3.6/site-packages/nose/importer.py\", line 47, in importFromPath\n",
      "    return self.importFromDir(dir_path, fqname)\n",
      "  File \"/Users/akihiroaida/.pyenv/versions/anaconda3-4.3.0/lib/python3.6/site-packages/nose/importer.py\", line 94, in importFromDir\n",
      "    mod = load_module(part_fqname, fh, filename, desc)\n",
      "  File \"/Users/akihiroaida/.pyenv/versions/anaconda3-4.3.0/lib/python3.6/imp.py\", line 234, in load_module\n",
      "    return load_source(name, filename, file)\n",
      "  File \"/Users/akihiroaida/.pyenv/versions/anaconda3-4.3.0/lib/python3.6/imp.py\", line 172, in load_source\n",
      "    module = _load(spec)\n",
      "  File \"<frozen importlib._bootstrap>\", line 675, in _load\n",
      "  File \"<frozen importlib._bootstrap>\", line 655, in _load_unlocked\n",
      "  File \"<frozen importlib._bootstrap_external>\", line 678, in exec_module\n",
      "  File \"<frozen importlib._bootstrap>\", line 205, in _call_with_frames_removed\n",
      "  File \"/Users/akihiroaida/.pyenv/versions/anaconda3-4.3.0/lib/python3.6/site-packages/pygpu/tests/test_tools.py\", line 5, in <module>\n",
      "    from .support import (guard_devsup, rand, check_flags, check_meta, check_all,\n",
      "  File \"/Users/akihiroaida/.pyenv/versions/anaconda3-4.3.0/lib/python3.6/site-packages/pygpu/tests/support.py\", line 32, in <module>\n",
      "    context = gpuarray.init(get_env_dev())\n",
      "  File \"/Users/akihiroaida/.pyenv/versions/anaconda3-4.3.0/lib/python3.6/site-packages/pygpu/tests/support.py\", line 29, in get_env_dev\n",
      "    raise RuntimeError(\"No test device specified.  Specify one using the DEVICE or GPUARRAY_TEST_DEVICE environment variables.\")\n",
      "RuntimeError: No test device specified.  Specify one using the DEVICE or GPUARRAY_TEST_DEVICE environment variables.\n",
      "\n",
      "----------------------------------------------------------------------\n",
      "Ran 7 tests in 0.005s\n",
      "\n",
      "FAILED (errors=7)\n"
     ]
    }
   ],
   "source": [
    "pygpu.test()"
   ]
  },
  {
   "cell_type": "code",
   "execution_count": null,
   "metadata": {
    "collapsed": true
   },
   "outputs": [],
   "source": []
  }
 ],
 "metadata": {
  "kernelspec": {
   "display_name": "Python 3",
   "language": "python",
   "name": "python3"
  },
  "language_info": {
   "codemirror_mode": {
    "name": "ipython",
    "version": 3
   },
   "file_extension": ".py",
   "mimetype": "text/x-python",
   "name": "python",
   "nbconvert_exporter": "python",
   "pygments_lexer": "ipython3",
   "version": "3.6.1"
  }
 },
 "nbformat": 4,
 "nbformat_minor": 2
}
